<?xml version='1.0'?>
  <sdf version='1.4'>
    <model name="korus_base">
      <static>false</static>
        <link name='base_link'>
          <pose>0 0 .0875 0 0 0</pose>
          <collision name='collision'>
            <geometry>
              <cylinder>
                <radius>.28</radius>
                <length>.275</length>
              </cylinder>
            </geometry>
          </collision>

          <collision name='caster_front_left_collision'>
            <pose>.18 .1 -.1225 0 1.57079632679 1.57079632679</pose>
            <geometry>
              <cylinder>
                <radius>.04</radius>
                <length>.02</length>
              </cylinder>
            </geometry>
            <surface>
              <friction>
                <ode>
                  <mu>0</mu>
                  <mu2>0</mu2>
                  <slip1>1.0</slip1>
                  <slip2>1.0</slip2>
                </ode>
              </friction>
            </surface>
          </collision>
          <visual name='caster_front_left_visual'>
            <pose>.18 .1 -.1225 0 1.57079632679 1.57079632679</pose>
            <geometry>
              <cylinder>
                <radius>.04</radius>
                <length>.02</length>
              </cylinder>
            </geometry>
            <material>
              <ambient>0 0 0 1</ambient>
              <diffuse>0 0 0 1</diffuse>
              <specular>0 0 0 1</specular>
              <emissive>0 0 0 0</emissive>
            </material>
          </visual>

          <collision name='caster_back_left_collision'>
            <pose>-.18 .1 -.1225 0 1.57079632679 1.57079632679</pose>
            <geometry>
              <cylinder>
                <radius>.04</radius>
                <length>.02</length>
              </cylinder>
            </geometry>
            <surface>
              <friction>
                <ode>
                  <mu>0</mu>
                  <mu2>0</mu2>
                  <slip1>1.0</slip1>
                  <slip2>1.0</slip2>
                </ode>
              </friction>
            </surface>
          </collision>
          <visual name='caster_back_left_visual'>
            <pose>-.18 .1 -.1225 0 1.57079632679 1.57079632679</pose>
            <geometry>
              <cylinder>
                <radius>.04</radius>
                <length>.02</length>
              </cylinder>
            </geometry>
            <material>
              <ambient>0 0 0 1</ambient>
              <diffuse>0 0 0 1</diffuse>
              <specular>0 0 0 1</specular>
              <emissive>0 0 0 0</emissive>
            </material>
          </visual>

          <collision name='caster_front_right_collision'>
            <pose>.18 -.1 -.1225 0 1.57079632679 1.57079632679</pose>
            <geometry>
              <cylinder>
                <radius>.04</radius>
                <length>.02</length>
              </cylinder>
            </geometry>
            <surface>
              <friction>
                <ode>
                  <mu>0</mu>
                  <mu2>0</mu2>
                  <slip1>1.0</slip1>
                  <slip2>1.0</slip2>
                </ode>
              </friction>
            </surface>
          </collision>
          <visual name='caster_front_right_visual'>
            <pose>.18 -.1 -.1225 0 1.57079632679 1.57079632679</pose>
            <geometry>
              <cylinder>
                <radius>.04</radius>
                <length>.02</length>
              </cylinder>
            </geometry>
            <material>
              <ambient>0 0 0 1</ambient>
              <diffuse>0 0 0 1</diffuse>
              <specular>0 0 0 1</specular>
              <emissive>0 0 0 0</emissive>
            </material>
          </visual>

          <collision name='caster_back_right_collision'>
            <pose>-.18 -.1 -.1225 0 1.57079632679 1.57079632679</pose>
            <geometry>
              <cylinder>
                <radius>.04</radius>
                <length>.02</length>
              </cylinder>
            </geometry>
            <surface>
              <friction>
                <ode>
                  <mu>0</mu>
                  <mu2>0</mu2>
                  <slip1>1.0</slip1>
                  <slip2>1.0</slip2>
                </ode>
              </friction>
            </surface>
          </collision>
          <visual name='caster_back_right_visual'>
            <pose>-.18 -.1 -.1225 0 1.57079632679 1.57079632679</pose>
            <geometry>
              <cylinder>
                <radius>.04</radius>
                <length>.02</length>
              </cylinder>
            </geometry>
            <material>
              <ambient>0 0 0 1</ambient>
              <diffuse>0 0 0 1</diffuse>
              <specular>0 0 0 1</specular>
              <emissive>0 0 0 0</emissive>
            </material>
          </visual>



          <visual name='visual'>
            <geometry>
              <cylinder>
                <radius>.28</radius>
                <length>.275</length>
              </cylinder>
            </geometry>
            <material>
              <ambient>1 .85 0 1</ambient>
              <diffuse>0 0 0 1</diffuse>
              <specular>0 0 0 1</specular>
              <emissive>0 0 0 1</emissive>
            </material>
          </visual>
        </link>

        <link name="left_wheel">
          <pose>0 .225 0 0 1.57079632679 1.57079632679</pose>
          <collision name="collision">
            <geometry>
              <cylinder>
                <radius>.075</radius>
                <length>.03</length>
              </cylinder>
            </geometry>
          </collision>
          <visual name="visual">
            <geometry>
              <cylinder>
                <radius>.075</radius>
                <length>.03</length>
              </cylinder>
            </geometry>
            <material>
              <ambient>0 0 0 1</ambient>
              <diffuse>0 0 0 1</diffuse>
              <specular>0 0 0 1</specular>
              <emissive>0 0 0 0</emissive>
            </material>
          </visual>
        </link>

        <link name="right_wheel">
          <pose>0 -.225 0 0 1.57079632679 1.57079632679</pose>
          <collision name="collision">
            <geometry>
              <cylinder>
                <radius>.075</radius>
                <length>.03</length>
              </cylinder>
            </geometry>
          </collision>
          <visual name="visual">
            <geometry>
              <cylinder>
                <radius>.075</radius>
                <length>.03</length>
              </cylinder>
            </geometry>
            <material>
              <ambient>0 0 0 1</ambient>
              <diffuse>0 0 0 1</diffuse>
              <specular>0 0 0 1</specular>
              <emissive>0 0 0 0</emissive>
            </material>
          </visual>
        </link>

        <joint type="revolute" name="left_wheel_joint">
          <pose>0 0 .225 0 0 0</pose>
          <child>left_wheel</child>
          <parent>base_link</parent>
          <axis>
            <xyz>0 1 0</xyz>
          </axis>
        </joint>

        <joint type="revolute" name="right_wheel_joint">
          <pose>0 0 -.225 0 0 0</pose>
          <child>right_wheel</child>
          <parent>base_link</parent>
          <axis>
            <xyz>0 1 0</xyz>
          </axis>
        </joint>
      </model>
    </sdf>
